Workbook

Sheet README
A1: Commerce Service - Function / API Backlog (traceable)
A2: Project Nexus (e-commerce & auction) | Commerce team | Built from Functions.xlsx (sheet "Commerce Service"), SRS_Commerce_Service_v1.md, DB_Commerce_v2.sql, and the other service sheets for contracts.
A4: How to trace
A5: System SRS section -> COM-* requirement (Trace_Matrix) -> Function ID (Backlog) -> API/trigger (Backlog, API_Catalog) -> Tables (Backlog, DB_Trace) -> Services (Integration_Map) -> Events (Event_Catalog) -> Test cases (Test_Cases).
A7: Sheets
A8: Backlog: 57 functions (48 from Functions.xlsx + 9 added). One row per function with priority, wave, SRS/COM links, tables, services, events, rules, errors.
A9: Trace_Matrix: every COM requirement with the functions, endpoints, tables, events, services and test counts. Coverage column is a formula.
A10: API_Catalog / Error_Codes: contracts of the HTTP APIs and a derived error-code registry (the "Error Codes" sheet referenced by Functions.xlsx does not exist).
A11: DB_Trace: 19 tables vs the functions that write/read them (counts are formulas, checked against the Backlog).
A12: Event_Catalog / Integration_Map: events and cross-service contracts with agreement status.
A13: Test_Cases: generated per function (happy, negative per error code, security, idempotency, contract) plus end-to-end scenarios.
A14: Gaps_Decisions: contract conflicts and open decisions (G01-G04 auction items are resolved by the agreed spec). SRS_Sync: the SRS edits needed to match the agreed spec.
... A22: Tech assumption (.NET): ASP.NET Core + EF Core (enum as string), MassTransit outbox/inbox, Quartz/Hangfire with distributed lock, PostgreSQL.

Sheet Backlog
A1: ID | B1: Module | C1: Function name | D1: Kind | E1: Endpoint / trigger | F1: Priority | G1: Wave | H1: Complexity | I1: Change vs Functions.xlsx | J1: Adjustment note | K1: System SRS ref | L1: COM requirement(s) | M1: Permission | N1: Tables written | O1: Tables read | P1: Integrated services | Q1: Events published | R1: Events consumed | S1: Idempotency / concurrency | T1: Key business rules | U1: Error codes | V1: Depends on | W1: Gaps | X1: # Test cases | Y1: Test coverage
A2: CART-01 | B2: Cart | C2: Get my cart / Lấy giỏ hàng của tôi | D2: Public API | E2: GET /api/v1/carts/me | F2: P0 | G2: 1 | H2: M | I2: ADJUSTED | J2: Catalog call re-pointed to CAT-39 (status/price/saleType) + CAT-24 (display data); stock via FUL-04. GET never creates a cart. | K2: 3.4.1.1; 3.4.1.5 | L2: COM-CART-001; COM-CART-005 | M2: CART.VIEW / Buyer | O2: carts, cart_items | P2: Catalog CAT-39 / CAT-24 (sync, degrade); Fulfillment FUL-04 (sync, optional, cache ~30s) | S2: Read-only | T2: Virtual empty cart when none; group by seller_id; show current price without overwriting snapshot; GET does not touch last_activity_at; degrade (200 + warnings) when Catalog/Fulfillment down. | V2: ORD-26 | W2: G09 | X2: =COUNTIF(Test_Cases!$B$2:$B$1000,A2) -> 4 | Y2: =IF(X2=0,"NO TEST",IF(X2<3,"THIN","OK")) -> OK
A3: CART-02 | B3: Cart | C3: Add item to cart / Thêm sản phẩm vào giỏ | D3: Public API | E3: POST /api/v1/carts/me/items | F3: P0 | G3: 1 | H3: L | I3: ADJUSTED | J3: UNIQUE(cart_id, sku_id) and carts.row_version now exist in DB v2. Auction-only product detected through CAT-39 (Reason=AUCTION_ONLY) -> 409 PRODUCT_IN_AUCTION. | K3: 3.4.1.1; 3.4.1.2 | L3: COM-CART-001; COM-CART-002 | M3: CART.UPDATE / Buyer | N3: carts, cart_items, outbox_messages | O3: checkout_groups, system_settings | P3: Catalog CAT-39 (sync, before TX); Fulfillment FUL-04 (soft check, before TX) | Q3: CartCreated; CartItemAdded | S3: Optimistic lock carts.row_version (retry 1-2x); UPSERT ON CONFLICT (cart_id, sku_id); partial unique uq_carts_active_buyer for first-cart race | T3: qty 1..MAX_QTY_PER_ITEM(99); <=MAX_CART_ITEMS(50) lines; cannot buy own product; no auction product; cart locked when checkout open; unit_price_snapshot = price at first add and never changes on merge; no inventory reservation on add. | U3: 400 VALIDATION_ERROR, 404 PRODUCT_NOT_FOUND, 409 PRODUCT_NOT_AVAILABLE, 409 INSUFFICIENT_STOCK, 409 CART_ITEM_LIMIT_EXCEEDED, 409 CANNOT_BUY_OWN_PRODUCT, 409 PRODUCT_IN_AUCTION, 409 CART_LOCKED, 503 CATALOG_UNAVAILABLE | V3: ORD-26; ORD-20 | W3: G09 | X3: =COUNTIF(Test_Cases!$B$2:$B$1000,A3) -> 15 | Y3: =IF(X3=0,"NO TEST",IF(X3<3,"THIN","OK")) -> OK
A4: CART-03 | B4: Cart | C4: Update cart item quantity / Cập nhật số lượng | D4: Public API | E4: PATCH /api/v1/carts/me/items/{cartItemId} | F4: P0 | G4: 1 | H4: M | I4: ADJUSTED | J4: Catalog check via CAT-39; row_version column now in DB v2. | K4: 3.4.1.3 | L4: COM-CART-003 | M4: CART.UPDATE / Buyer | N4: cart_items, carts, outbox_messages | O4: checkout_groups | P4: Catalog CAT-39 (sync); Fulfillment FUL-04 (sync) | Q4: CartItemUpdated | S4: Optimistic lock carts.row_version (retry 1-2x then 409 CONCURRENT_UPDATE) | T4: qty>=1 and <=MAX_QTY_PER_ITEM and <= available stock; other buyer's item returns 404; refreshes last_activity_at; does not change unit_price_snapshot. | U4: 400 VALIDATION_ERROR, 404 CART_ITEM_NOT_FOUND, 409 INSUFFICIENT_STOCK, 409 PRODUCT_NOT_AVAILABLE, 409 CONCURRENT_UPDATE, 409 CART_LOCKED | V4: CART-02 | W4: G09 | X4: =COUNTIF(Test_Cases!$B$2:$B$1000,A4) -> 11 | Y4: =IF(X4=0,"NO TEST",IF(X4<3,"THIN","OK")) -> OK
A5: CART-04 | B5: Cart | C5: Remove cart item / Xoá một dòng khỏi giỏ | D5: Public API | E5: DELETE /api/v1/carts/me/items/{cartItemId} | F5: P0 | G5: 1 | H5: S | I5: ADJUSTED | J5: Function name was blank in Functions.xlsx (cell B5); filled in. | K5: 3.4.1.4 | L5: COM-CART-004 | M5: CART.REMOVE_ITEM / Buyer | N5: cart_items, carts, outbox_messages | O5: checkout_groups | P5: - | Q5: CartItemRemoved | S5: DELETE is idempotent (200 even if the item is already gone) | T5: Hard delete of cart_items (no deleted_at); recalc item_count/subtotal; cart stays ACTIVE when empty; blocked while checkout open (CART_LOCKED). | U5: 409 CART_LOCKED | V5: CART-02 | X5: =COUNTIF(Test_Cases!$B$2:$B$1000,A5) -> 4 | Y5: =IF(X5=0,"NO TEST",IF(X5<3,"THIN","OK")) -> OK
A6: CART-05 | B6: Cart | C6: Bulk remove / clear cart / Xoá nhiều dòng hoặc xoá hết | D6: Public API | E6: POST /api/v1/carts/me/items:bulk-remove | F6: P1 | G6: 1 | H6: S | I6: UNCHANGED | K6: 3.4.1.4 | L6: COM-CART-004 | M6: CART.REMOVE_ITEM / Buyer | N6: cart_items, carts, outbox_messages | O6: checkout_groups | P6: - | Q6: CartItemRemoved (1 event per batch) | S6: Idempotent: unknown ids ignored | T6: cartItemIds 1..100 XOR all=true; POST :bulk-remove instead of DELETE with body. | U6: 400 VALIDATION_ERROR, 409 CART_LOCKED | V6: CART-04 | X6: =COUNTIF(Test_Cases!$B$2:$B$1000,A6) -> 5 | Y6: =IF(X6=0,"NO TEST",IF(X6<3,"THIN","OK")) -> OK
A7: CART-06 | B7: Cart | C7: Validate cart / Kiểm tra giỏ hàng trước checkout | D7: Public API | E7: POST /api/v1/carts/me/validate (+ internal CartValidator dùng lại ở CHK-01/02) | F7: P0 | G7: 1 | H7: M | I7: ADJUSTED | J7: Use CAT-39 (Purpose=CART/CHECKOUT) as the single source for 'is purchasable'; PRICE_CHANGED is a warning, OUT_OF_STOCK/INACTIVE block checkout. | K7: 3.4.1.6 | L7: COM-CART-006 | M7: CART.VIEW / Buyer | O7: carts, cart_items | P7: Catalog CAT-39 / CAT-24 (sync); Fulfillment FUL-04 (sync) | S7: Read-only; internal CartValidator is reused by CHK-01/CHK-02 | T7: Report only, never auto-fix the cart; if CHECKOUT_PRICE_REVALIDATION=true and price changed return PRICE_CHANGED with the new price so the buyer confirms (SRS COM-CART-006); other issues: OUT_OF_STOCK | INACTIVE | SELLER_SUSPENDED | QTY_EXCEEDS_STOCK. | U7: 409 CART_EMPTY, 503 CATALOG_UNAVAILABLE | V7: CART-02 | W7: G09 | X7: =COUNTIF(Test_Cases!$B$2:$B$1000,A7) -> 6 | Y7: =IF(X7=0,"NO TEST",IF(X7<3,"THIN","OK")) -> OK
A8: CART-07 | B8: Cart | C8: Cart price calculation / Tính giá giỏ hàng | D8: Internal component | E8: PricingService.calculate(items, address?, vouchers?) | F8: P0 | G8: 1 | H8: L | I8: UNCHANGED | J8: Blocked on config PLATFORM_MARKUP_PERCENT (not seeded in DB v2) and tax decision. | K8: 3.4.1.5 | L8: COM-CART-005; COM-CHK-003 | M8: System (internal) | O8: system_settings | P8: DSC-02 (internal call) | S8: Pure function | T8: Shared pricing: product discount -> shop discount -> markup -> system voucher -> ship; invariant total = seller_receive + platform_fee + shipping_fee; platform_fee may be negative. | U8: 422 PRICING_ERROR | V8: DSC-02; ORD-26 | W8: G20; G23 | X8: =COUNTIF(Test_Cases!$B$2:$B$1000,A8) -> 4 | Y8: =IF(X8=0,"NO TEST",IF(X8<3,"THIN","OK")) -> OK
A9: CART-08 | B9: Cart | C9: Cart summary (badge) / Số lượng giỏ hàng | D9: Public API | E9: GET /api/v1/carts/me/summary | F9: P1 | G9: 1 | H9: S | I9: UNCHANGED | K9: 3.4.1.5 | L9: COM-CART-005 | M9: CART.VIEW / Buyer | O9: carts | P9: - | S9: Read-only (cacheable) | T9: Reads denormalized item_count and subtotal_amount; returns 0 when no cart (no auto-create). | X9: =COUNTIF(Test_Cases!$B$2:$B$1000,A9) -> 3 | Y9: =IF(X9=0,"NO TEST",IF(X9<3,"THIN","OK")) -> OK
A10: CART-09 | B10: Cart | C10: Expire inactive carts / Job hết hạn giỏ hàng | D10: Job | E10: chạy mỗi giờ (@Scheduled + ShedLock) | F10: P1 | G10: 1 | H10: S | I10: UNCHANGED | J10: Interval 'hourly' differs from 1-minute jobs elsewhere; confirm. | K10: 3.4.1.1 | L10: COM-CART-007 | M10: System | N10: carts, outbox_messages | O10: checkout_groups, system_settings | P10: - | Q10: CartExpired | S10: SELECT ... FOR UPDATE SKIP LOCKED, batch 500, ShedLock | T10: ACTIVE carts with last_activity_at older than CART_EXPIRATION_DAYS(7) become ABANDONED; skip carts with an open checkout; no delete. | V10: ORD-20; ORD-26 | W10: G26 | X10: =COUNTIF(Test_Cases!$B$2:$B$1000,A10) -> 3 | Y10: =IF(X10=0,"NO TEST",IF(X10<3,"THIN","OK")) -> OK
A11: CART-10 | B11: Cart | C11: Merge guest cart on login / Gộp giỏ khách (OPTIONAL) | D11: Public API | E11: POST /api/v1/carts/me/merge | F11: P2 | G11: 4 | H11: S | I11: ADJUSTED | J11: WON'T for MVP by default: SRS COM-CART-009 says login required, no merge (OQ-04). Kept only as an optional placeholder. | K11: 3.4.1.1 | L11: COM-CART-009 | M11: CART.UPDATE / Buyer | N11: carts, cart_items, outbox_messages | O11: system_settings | P11: Catalog CAT-39; Fulfillment FUL-04 | Q11: CartItemAdded | S11: Same as CART-02 | T11: <=50 items; each item follows CART-02 rules; skipped items returned with reason. | U11: 400 VALIDATION_ERROR, 409 CART_LOCKED | V11: CART-02 | W11: G23 | X11: =COUNTIF(Test_Cases!$B$2:$B$1000,A11) -> 6 | Y11: =IF(X11=0,"NO TEST",IF(X11<3,"THIN","OK")) -> OK
A12: CART-11 | B12: Cart | C12: Cleanup on Product/User events / Dọn giỏ theo sự kiện | D12: Event consumer | E12: topics: catalog.*, user.* | F12: P1 | G12: 1 | H12: M | I12: UNCHANGED | K12: 3.4.1.4 (cart integrity) | L12: COM-CART-008; COM-PLT-003 | M12: System | N12: inbox_messages, cart_items, carts | P12: Catalog / User events | R12: ProductDeleted; ProductStatusChanged; UserDeleted | S12: Inbox (message_id, consumer); at-least-once; batch 500 carts per TX | T12: ProductDeleted removes cart lines; INACTIVE only flagged (shown in CART-01); UserDeleted marks carts ABANDONED + deleted_at. | V12: ORD-24 | X12: =COUNTIF(Test_Cases!$B$2:$B$1000,A12) -> 4 | Y12: =IF(X12=0,"NO TEST",IF(X12<3,"THIN","OK")) -> OK
A13: CHK-01 | B13: Checkout | C13: Checkout preview / Xem trước thanh toán | D13: Public API | E13: POST /api/v1/checkout/preview | F13: P0 | G13: 2 | H13: L | I13: ADJUSTED | J13: Wallet balance comes from Wallet WAL-02 (Payment was split into the Wallet service). Catalog via CAT-39/24; quote via FUL-12. | K13: 3.4.2.1; 3.4.1.5 | L13: COM-CHK-001; COM-CHK-003; COM-CHK-004 | M13: CHECKOUT.START / Buyer | O13: carts, cart_items, discount_codes, discount_code_scopes, discount_code_usages, system_settings | P13: Catalog CAT-39/24; Fulfillment FUL-12 shipping quote (timeout 3000ms); Wallet WAL-02 balance | S13: Read-only; returns quoteId (short TTL) reused by CHK-02 | T13: Split by seller; invalid voucher goes to invalidVouchers (does not fail); quote failure returns 200 with null ship fee + warning; COD not supported. | U13: 409 CART_EMPTY, 409 CART_INVALID | V13: CART-06; CART-07; DSC-02 | W13: G05; G09 | X13: =COUNTIF(Test_Cases!$B$2:$B$1000,A13) -> 6 | Y13: =IF(X13=0,"NO TEST",IF(X13<3,"THIN","OK")) -> OK
A14: CHK-02 | B14: Checkout | C14: Create checkout (group + orders) / Tạo checkout và đơn hàng | D14: Public API | E14: POST /api/v1/checkout | F14: P0 | G14: 2 | H14: XL | I14: ADJUSTED | J14: Inventory reservation contract differs from FUL-06 (event per order) - see G06. Reputation check endpoint differs from User GRPC-04 - see G11. | K14: 3.4.2.1; 3.4.3.1; 3.4.3.7; 3.4.3.8 | L14: COM-CHK-001; COM-CHK-002; COM-CHK-003; COM-CHK-005; COM-CHK-006; COM-CHK-007; COM-ORD-001; COM-PLT-001 | M14: CHECKOUT.START + ORDER.CREATE / Buyer | N14: idempotency_keys, checkout_groups, orders, order_items, order_status_history, discount_codes, discount_code_usages, saga_state, daily_order_sequences, outbox_messages | O14: carts, cart_items, system_settings | P14: Catalog CAT-39 (re-price); User status-trust (GRPC-04 equivalent, undefined); Fulfillment inventory reservation (all-or-nothing per group) | Q14: CheckoutStarted; OrderCreated (per order) | R14: InventoryReserved (Fulfillment, async variant) | S14: Idempotency-Key required; CheckoutSaga (TX-1 / reserve / TX-2 or compensate TX-3); uq_checkout_groups_open_cart | T14: 1 cart -> 1 checkout_group + N orders (per seller); deadline = now + CHECKOUT_TIMEOUT_MINUTES(15); amounts and snapshots frozen; cart kept until paid; SLA create order <= 1.5s. | U14: 400 VALIDATION_ERROR, 409 PRICE_CHANGED, 409 CART_INVALID, 409 CHECKOUT_ALREADY_OPEN, 409 INSUFFICIENT_STOCK, 409 VOUCHER_INVALID, 403 REPUTATION_RESTRICTED, 409 IDEMPOTENCY_KEY_CONFLICT, 409 REQUEST_IN_PROGRESS, 503 FULFILLMENT_UNAVAILABLE | V14: ORD-17; ORD-18; ORD-19; ORD-20; ORD-21; DSC-03; CART-06; CART-07 | W14: G06; G11 | X14: =COUNTIF(Test_Cases!$B$2:$B$1000,A14) -> 18 | Y14: =IF(X14=0,"NO TEST",IF(X14<3,"THIN","OK")) -> OK
A15: CHK-03 | B15: Checkout | C15: Pay checkout group / Thanh toán nhóm đơn | D15: Public API | E15: POST /api/v1/checkout-groups/{checkoutGroupId}/pay | F15: P0 | G15: 2 | H15: L | I15: ADJUSTED | J15: Payment is the Wallet service: WALLET -> event OrderCheckoutRequested (WAL-05A); VNPAY -> WAL-05B direct gateway. Functions.xlsx assumed HTTP POST /internal/v1/payments; contract must be aligned. | K15: 3.4.2.2 | L15: COM-PAY-001 | M15: CHECKOUT.PAY (NEW) / Buyer | N15: checkout_groups, orders, saga_state, idempotency_keys, outbox_messages | O15: orders, checkout_groups | P15: Wallet WAL-05A (event) / WAL-05B (HTTP); payment status query (undefined) | Q15: OrderCheckoutRequested (WALLET path, per WAL-05A) | S15: Idempotency-Key required; optimistic lock row_version; attempt counter payment_attempt_count (max PAYMENT_RETRY_LIMIT=3) | T15: Never returns PAID synchronously (202 PAYMENT_PROCESSING; PAID only via PAY-01); Commerce never debits money itself; no cancel while PAYMENT_PROCESSING. | U15: 404 CHECKOUT_GROUP_NOT_FOUND, 409 CHECKOUT_NOT_PAYABLE, 410 DEADLINE_EXPIRED, 402 INSUFFICIENT_WALLET_BALANCE, 409 PAYMENT_ATTEMPT_LIMIT_REACHED, 502 PAYMENT_GATEWAY_ERROR, 202 PAYMENT_PROCESSING | V15: CHK-02; ORD-19 | W15: G05 | X15: =COUNTIF(Test_Cases!$B$2:$B$1000,A15) -> 12 | Y15: =IF(X15=0,"NO TEST",IF(X15<3,"THIN","OK")) -> OK
A16: CHK-04 | B16: Checkout | C16: Get checkout group / Xem trạng thái checkout | D16: Public API | E16: GET /api/v1/checkout-groups/{checkoutGroupId} | F16: P0 | G16: 2 | H16: S | I16: UNCHANGED | J16: No list endpoint for checkout groups although idx_checkout_groups_buyer exists. | K16: 3.4.2.3; 3.4.3.3 | L16: COM-CHK-009 | M16: ORDER.VIEW / Buyer (own) | O16: checkout_groups, orders | P16: - | S16: Read-only (FE polls every 2-3s, ~2 min) | T16: Own group only (404 otherwise); status set PENDING_PAYMENT | PAYMENT_PROCESSING | PAID | CANCELLED | EXPIRED. | U16: 404 CHECKOUT_GROUP_NOT_FOUND | V16: CHK-02 | X16: =COUNTIF(Test_Cases!$B$2:$B$1000,A16) -> 4 | Y16: =IF(X16=0,"NO TEST",IF(X16<3,"THIN","OK")) -> OK
A17: CHK-05 | B17: Checkout | C17: Cancel checkout group / Huỷ checkout chưa thanh toán | D17: Public API | E17: POST /api/v1/checkout-groups/{checkoutGroupId}/cancel | F17: P0 | G17: 2 | H17: M | I17: UNCHANGED | J17: Matches COM-CHK-010 (cancel the whole group, never single unpaid orders). Events spec API 13 conflicts: see G35. | K17: 3.4.2.4 | L17: COM-CHK-010; COM-CNL-001 | M17: ORDER.CANCEL / Buyer | N17: checkout_groups, orders, order_cancellations, order_status_history, discount_code_usages, discount_codes, saga_state, outbox_messages | P17: Wallet (payment-in-flight check, undefined); Fulfillment release via OrderCancelled event (FUL-10) | Q17: OrderCancelled (per order); CheckoutCancelled | S17: CAS on row_version | T17: Only PENDING_PAYMENT groups; sole path to cancel an unpaid normal order; was_paid=false so no refund; inventory_released updated by ORD-22. | U17: 409 CHECKOUT_NOT_CANCELLABLE, 409 PAYMENT_IN_PROGRESS | V17: ORD-18; DSC-04 | W17: G05 | X17: =COUNTIF(Test_Cases!$B$2:$B$1000,A17) -> 7 | Y17: =IF(X17=0,"NO TEST",IF(X17<3,"THIN","OK")) -> OK
A18: CHK-06 | B18: Checkout | C18: Expire unpaid checkout / Job hết hạn thanh toán | D18: Job | E18: mỗi 1 phút (+ consumer InventoryReservationExpired làm lưới an toàn) | F18: P0 | G18: 2 | H18: M | I18: ADJUSTED | J18: Interval 15 s per Events spec 3.4 (SRS leaves OPEN). Payment status lookup still undefined (G05). | K18: 3.4.2.4; 3.4.3.8 | L18: COM-CHK-008 | M18: System | N18: checkout_groups, orders, order_cancellations, order_status_history, discount_code_usages, discount_codes, saga_state, outbox_messages | O18: checkout_groups | P18: Wallet payment status by referenceIds (batch, undefined); Fulfillment release via event | Q18: CheckoutExpired; OrderCancelled (PAYMENT_TIMEOUT, SYSTEM) | S18: SKIP LOCKED batch 100; every 15 s (spec, PROPOSED, OQ-19) | T18: Cancel group where status=PENDING_PAYMENT and payment_deadline_at < now; if Payment says SUCCEEDED hand over to PAY-01; never blind-cancel. | V18: ORD-18; DSC-04; PAY-01 | W18: G05 | X18: =COUNTIF(Test_Cases!$B$2:$B$1000,A18) -> 4 | Y18: =IF(X18=0,"NO TEST",IF(X18<3,"THIN","OK")) -> OK
A19: PAY-01 | B19: Payment (Commerce side) | C19: Handle payment result / Nhận kết quả thanh toán | D19: Event consumer | E19: PaymentSucceeded | PaymentFailed | PaymentExpired (event do Payment Service phát, cần chốt contract) | F19: P0 | G19: 2 | H19: XL | I19: ADJUSTED | J19: Wallet events are the target (Payment split, OQ-17); Events spec keeps temporary names PaymentSucceeded / PaymentFailed behind an adapter. VNPAY success event does not exist yet. | K19: 3.4.2.3; 3.4.3.7; 3.4.3.8 | L19: COM-PAY-002; COM-PAY-003; COM-PAY-004; COM-AUC-007; COM-AUC-008 | M19: System (service-to-service, JWT dịch vụ / mTLS) | N19: inbox_messages, checkout_groups, orders, auction_orders, order_status_history, order_refunds, discount_codes, discount_code_usages, cart_items, carts, saga_state, outbox_messages | O19: orders, order_items, auction_orders | P19: Wallet events (consume); Fulfillment confirm via OrderPaid (FUL-09); refund via OrderRefundRequested | Q19: OrderPaid (per order); OrderPaymentFailed; CheckoutCompleted (not in SRS 5.2); OrderRefundRequested (late/mismatch) | R19: WalletDebitedSuccess / WalletDebitFailed (target); PaymentSucceeded / PaymentFailed / PaymentExpired (as written) | S19: Inbox (message_id, consumer); optimistic lock row_version | T19: amount must equal total_amount else no PAID + refund; late payment (group EXPIRED/CANCELLED) -> full refund by checkout_group_id; failed/expired -> group back to PENDING_PAYMENT (<=3 attempts); seller_respond_deadline_at = paid_at + 24h. | V19: ORD-18; DSC-04; ORD-19; CHK-03; AO-03 | W19: G05 | X19: =COUNTIF(Test_Cases!$B$2:$B$1000,A19) -> 5 | Y19: =IF(X19=0,"NO TEST",IF(X19<3,"THIN","OK")) -> OK
A20: DSC-01 | B20: Discount | C20: List available vouchers / Danh sách voucher khả dụng | D20: Public API | E20: GET /api/v1/vouchers/available?cartItemIds=&sellerId=&page=&size= | F20: P1 | G20: 2 | H20: M | I20: UNCHANGED | K20: - (not in system SRS; from DB design) | L20: COM-DSC-002 | M20: CART.VIEW / Buyer | O20: discount_codes, discount_code_scopes, discount_code_usages | P20: Catalog (category/product of items for CATEGORY/SKU scope) | S20: Read-only | T20: ACTIVE, visible, in period, not exhausted, per-user limit not reached; hidden codes still usable when typed. | U20: 404 SELLER_NOT_FOUND | W20: G12 | X20: =COUNTIF(Test_Cases!$B$2:$B$1000,A20) -> 5 | Y20: =IF(X20=0,"NO TEST",IF(X20<3,"THIN","OK")) -> OK
A21: DSC-02 | B21: Discount | C21: Validate & calculate voucher / Kiểm tra và tính giảm giá | D21: Internal component | E21: VoucherService.validateAndCalculate(code, userId, scopeContext) | F21: P0 | G21: 1 | H21: L | I21: UNCHANGED | K21: - (not in system SRS; from DB design) | L21: COM-DSC-003; COM-DSC-004; COM-DSC-005 | M21: System (internal) | O21: discount_codes, discount_code_scopes, discount_code_usages | P21: - | S21: Pure / read-only | T21: PERCENT = min(eligible*value/100, max_discount_amount); FIXED = min(value, eligible); order PRODUCT -> SHOP -> markup -> SYSTEM; 1 SYSTEM/group, 1 SHOP/order, 1 PRODUCT/item; SYSTEM pro-rata with remainder on last order. | W21: G12 | X21: =COUNTIF(Test_Cases!$B$2:$B$1000,A21) -> 3 | Y21: =IF(X21=0,"NO TEST",IF(X21<3,"THIN","OK")) -> OK
A22: DSC-03 | B22: Discount | C22: Reserve vouchers / Giữ lượt voucher | D22: Internal component | E22: VoucherService.reserve(checkoutGroupId, orderId?, userId, codes) – gọi trong TX-1 của CHK-02 | F22: P0 | G22: 2 | H22: M | I22: UNCHANGED | K22: - (not in system SRS; from DB design) | L22: COM-DSC-004; COM-DSC-006 | M22: System (internal) | N22: discount_codes, discount_code_usages | O22: discount_code_usages | P22: - | S22: Conditional UPDATE (atomic counter) + pg_advisory_xact_lock(code,user); runs inside CHK-02 TX-1 | T22: reserved_count+1 only if used+reserved < max_uses_total; SYSTEM usage binds checkout_group_id, SHOP/PRODUCT binds order_id. | V22: DSC-02 | X22: =COUNTIF(Test_Cases!$B$2:$B$1000,A22) -> 3 | Y22: =IF(X22=0,"NO TEST",IF(X22<3,"THIN","OK")) -> OK
A23: DSC-04 | B23: Discount | C23: Confirm / Release voucher usage / Xác nhận hoặc trả lại lượt voucher | D23: Internal component | E23: VoucherService.confirm(groupId) / release(orderId|groupId, reason) | F23: P0 | G23: 2 | H23: M | I23: UNCHANGED | J23: BA decision pending: do vouchers return when a buyer cancels after paying. | K23: - (not in system SRS; from DB design) | L23: COM-DSC-006 | M23: System (internal) | N23: discount_codes, discount_code_usages | O23: discount_code_usages | P23: - | S23: Idempotent (USED/RELEASED rows skipped); called inside PAY-01 / CHK-05 / CHK-06 / ORD-05/06/09 TX | T23: confirm: RESERVED->USED (used+1, reserved-1); release: RESERVED/USED->RELEASED. | V23: DSC-03 | W23: G18 | X23: =COUNTIF(Test_Cases!$B$2:$B$1000,A23) -> 3 | Y23: =IF(X23=0,"NO TEST",IF(X23<3,"THIN","OK")) -> OK
A24: DSC-05 | B24: Discount | C24: Create voucher / Tạo voucher | D24: Public API | E24: POST /api/v1/vouchers | F24: P1 | G24: 4 | H24: M | I24: NEW | J24: PROPOSED. DB has discount_codes/discount_code_scopes but Functions.xlsx has no API that creates vouchers; privileges DISCOUNT.* are not in SRS 2.7. | K24: - (gap: no system SRS section) | L24: COM-DSC-001; COM-DSC-003 | M24: DISCOUNT.CREATE (NEW) / Admin, Seller | N24: discount_codes, discount_code_scopes, outbox_messages | O24: discount_codes | P24: Catalog (validate SHOP/PRODUCT/SKU/CATEGORY ref, optional) | S24: Unique lower(code) among non-deleted | T24: Admin creates SYSTEM (owner NULL); Seller creates SHOP/PRODUCT (owner = JWT sub); PERCENT<=100; ends_at>starts_at; scope ALL iff ref NULL. | U24: 400 VALIDATION_ERROR, 409 VOUCHER_CODE_EXISTS, 403 FORBIDDEN | V24: DSC-02 | W24: G12; G29 | X24: =COUNTIF(Test_Cases!$B$2:$B$1000,A24) -> 8 | Y24: =IF(X24=0,"NO TEST",IF(X24<3,"THIN","OK")) -> OK
A25: DSC-06 | B25: Discount | C25: Update / activate / delete voucher / Sửa, bật tắt, xoá voucher | D25: Public API | E25: PATCH /api/v1/vouchers/{voucherId} | F25: P1 | G25: 4 | H25: M | I25: NEW | J25: PROPOSED. Update, activate/deactivate and soft-delete a voucher. | K25: - (gap: no system SRS section) | L25: COM-DSC-001 | M25: DISCOUNT.UPDATE (NEW) / Admin, Seller (own) | N25: discount_codes, discount_code_scopes | O25: discount_codes, discount_code_usages | P25: - | S25: Optimistic update; counters never edited directly | T25: Owner only; status DRAFT->ACTIVE->INACTIVE/EXPIRED; once used, value/type are immutable; soft delete via deleted_at. | U25: 400 VALIDATION_ERROR, 404 VOUCHER_NOT_FOUND, 409 VOUCHER_ALREADY_USED, 403 FORBIDDEN | V25: DSC-05 | W25: G12; G29 | X25: =COUNTIF(Test_Cases!$B$2:$B$1000,A25) -> 8 | Y25: =IF(X25=0,"NO TEST",IF(X25<3,"THIN","OK")) -> OK
A26: DSC-07 | B26: Discount | C26: List vouchers for management / Quản lý danh sách voucher | D26: Public API | E26: GET /api/v1/vouchers | F26: P2 | G26: 4 | H26: S | I26: NEW | J26: PROPOSED. Management list (seller: own codes; admin: all) - distinct from buyer-facing DSC-01. | K26: - (gap: no system SRS section) | L26: COM-DSC-001 | M26: DISCOUNT.VIEW (NEW) / Admin, Seller (own) | O26: discount_codes, discount_code_scopes | P26: - | S26: Read-only | T26: Filter by status/scope; paging <=50; seller sees only own owner_seller_id. | U26: 403 FORBIDDEN | V26: DSC-05 | W26: G12; G29 | X26: =COUNTIF(Test_Cases!$B$2:$B$1000,A26) -> 4 | Y26: =IF(X26=0,"NO TEST",IF(X26<3,"THIN","OK")) -> OK
A27: DSC-08 | B27: Discount | C27: Expire vouchers / Job hết hạn voucher | D27: Job | E27: Scheduled - hourly | F27: P2 | G27: 4 | H27: S | I27: NEW | J27: PROPOSED job: ACTIVE codes whose ends_at < now become EXPIRED. | K27: - (gap: no system SRS section) | L27: COM-DSC-007 | M27: System | N27: discount_codes | O27: discount_codes | P27: - | S27: Batch + SKIP LOCKED | T27: Does not touch RESERVED usages (they are released by checkout expiry). | V27: DSC-05 | W27: G12 | X27: =COUNTIF(Test_Cases!$B$2:$B$1000,A27) -> 3 | Y27: =IF(X27=0,"NO TEST",IF(X27<3,"THIN","OK")) -> OK
A28: ORD-01 | B28: Order | C28: List my orders / Lịch sử đơn hàng của tôi | D28: Public API | E28: GET /api/v1/orders | F28: P0 | G28: 3 | H28: M | I28: UNCHANGED | K28: 3.4.3.4 | L28: COM-ORD-002; COM-ORD-012 | M28: ORDER.LIST / Buyer (own) | O28: orders, auction_orders, order_items | P28: User batch lookup of seller name (cache; endpoint undefined) | S28: Read-only | T28: UNION ALL orders + auction_orders; buyer_id = JWT sub; deleted_at IS NULL; size<=100; range<=1 year; sort whitelist. | U28: 400 VALIDATION_ERROR | W28: G11 | X28: =COUNTIF(Test_Cases!$B$2:$B$1000,A28) -> 5 | Y28: =IF(X28=0,"NO TEST",IF(X28<3,"THIN","OK")) -> OK
A29: ORD-02 | B29: Order | C29: Get order detail / Chi tiết & theo dõi đơn hàng | D29: Public API | E29: GET /api/v1/orders/{orderId}?orderType=REGULAR|AUCTION | F29: P0 | G29: 3 | H29: L | I29: UNCHANGED | K29: 3.4.3.3 | L29: COM-ORD-003 | M29: ORDER.VIEW / Buyer (own), Seller (own), Admin, Support | O29: orders, auction_orders, order_items, order_status_history, order_cancellations, order_refunds, order_invoices | P29: Fulfillment FUL-18/19/20 (shipment, degrade to null) | S29: Read-only | T29: Buyer own / Seller own (paid_at not null only) / Admin, Support all; forbidden => 404; amounts shown by role (platformFee admin only); allowedActions from state machine. | U29: 404 ORDER_NOT_FOUND | V29: ORD-18 | X29: =COUNTIF(Test_Cases!$B$2:$B$1000,A29) -> 5 | Y29: =IF(X29=0,"NO TEST",IF(X29<3,"THIN","OK")) -> OK
A30: ORD-03 | B30: Order | C30: Seller order list / Danh sách đơn của seller | D30: Public API | E30: GET /api/v1/seller/orders | F30: P0 | G30: 3 | H30: M | I30: UNCHANGED | K30: 3.4.3.4 | L30: COM-ORD-004 | M30: ORDER.LIST / Seller (own) | O30: orders, auction_orders | P30: - | S30: Read-only | T30: paid_at IS NOT NULL mandatory; status=PENDING_PAYMENT -> 400; statusCounts in one GROUP BY; PAID near deadline first. | U30: 400 VALIDATION_ERROR | X30: =COUNTIF(Test_Cases!$B$2:$B$1000,A30) -> 4 | Y30: =IF(X30=0,"NO TEST",IF(X30<3,"THIN","OK")) -> OK
A31: ORD-04 | B31: Order | C31: Seller accept order / Seller xác nhận đơn | D31: Public API | E31: POST /api/v1/seller/orders/{orderId}/accept?orderType= | F31: P0 | G31: 3 | H31: M | I31: UNCHANGED | J31: Event renamed OrderConfirmed per Events spec; Fulfillment FUL-13 must switch the listener name (G13). Shipment creation at CONFIRMED is OQ-20 (behind flag). Status CONFIRMED exists in DB v2. | K31: 3.4.3.2 | L31: COM-ORD-005; COM-AUC-007 | M31: ORDER.CONFIRM (SRS OQ-12) / Seller | N31: orders, auction_orders, order_status_history, outbox_messages | O31: orders, auction_orders | P31: Fulfillment creates shipment asynchronously on OrderConfirmed (FUL-13 listener name to switch, G13) | Q31: OrderConfirmed (renamed from OrderSellerAccepted, spec 2.4.5 PROPOSED) | S31: CAS UPDATE ... WHERE status='PAID' AND row_version=? | T31: seller_id = sub; status PAID; now <= seller_respond_deadline_at; sets seller_accepted_at. | U31: 404 ORDER_NOT_FOUND, 409 ORDER_STATE_CONFLICT, 410 DEADLINE_EXPIRED | V31: ORD-18 | W31: G14 | X31: =COUNTIF(Test_Cases!$B$2:$B$1000,A31) -> 9 | Y31: =IF(X31=0,"NO TEST",IF(X31<3,"THIN","OK")) -> OK
A32: ORD-05 | B32: Order | C32: Seller reject order / Seller từ chối đơn | D32: Public API | E32: POST /api/v1/seller/orders/{orderId}/reject?orderType= | F32: P0 | G32: 3 | H32: L | I32: ADJUSTED | J32: reasonCode is frozen to SELLER_REJECTED (SRS 5.6); Functions.xlsx codes OUT_OF_STOCK / CANNOT_FULFILL / OTHER go into reasonNote. Notification and User listen to OrderSellerRejected: they must listen to OrderCancelled instead (G13). | K32: 3.4.3.2; 3.4.2.4 | L32: COM-ORD-006; COM-CNL-001; COM-RFD-001; COM-AUC-008 | M32: ORDER.REJECT (SRS OQ-12) / Seller | N32: orders, auction_orders, order_cancellations, order_refunds, order_status_history, discount_codes, discount_code_usages, saga_state, outbox_messages | O32: orders, auction_orders | P32: Wallet refund via OrderRefundRequested; Fulfillment release via OrderCancelled; User penalty via event | Q32: OrderCancelled (SELLER_REJECTED, SELLER); OrderRefundRequested | S32: OrderCancellationSaga TX-1 (CAS), rest async | T32: status in {PAID, CONFIRMED}; reasonCode SELLER_REJECTED + reasonNote; 100% refund; was_paid=true. | U32: 409 ORDER_STATE_CONFLICT | V32: ORD-18; ORD-06; DSC-04 | W32: G05; G13 | X32: =COUNTIF(Test_Cases!$B$2:$B$1000,A32) -> 6 | Y32: =IF(X32=0,"NO TEST",IF(X32<3,"THIN","OK")) -> OK
A33: ORD-06 | B33: Order | C33: Cancel order / Huỷ đơn (Buyer, Support, Admin) | D33: Public API | E33: POST /api/v1/orders/{orderId}/cancel?orderType= | F33: P0 | G33: 3 | H33: XL | I33: ADJUSTED | J33: Unpaid normal orders must use CHK-05 (COM-CHK-010); Events spec API 13 allows per-order cancel of PENDING_PAYMENT, SRS wins (G35). reasonCode BUYER_CANCELLED or ADMIN_CANCELLED + reasonNote. Write refund data only to order_refunds. | K33: 3.4.2.4 | L33: COM-CNL-001; COM-CNL-002; COM-CNL-003; COM-CNL-004; COM-RFD-001; COM-AUC-008 | M33: ORDER.CANCEL / Buyer (own), Support, Admin | N33: orders, auction_orders, order_cancellations, order_refunds, order_status_history, discount_codes, discount_code_usages, saga_state, idempotency_keys, outbox_messages | O33: checkout_groups | P33: Wallet refund (async, WAL-06); Fulfillment FUL-10 release (async) | Q33: OrderCancelled; OrderRefundRequested (if was_paid) | S33: Idempotency-Key required; OrderCancellationSaga; UNIQUE order_cancellations per order | T33: Buyer: PAID normal order (not yet CONFIRMED) or PENDING_PAYMENT/PAID auction order; Support/Admin: PAID or CONFIRMED; reasonCode from frozen list; no cancel after SHIPPING. | U33: 404 ORDER_NOT_FOUND, 409 ORDER_NOT_CANCELLABLE, 409 PAYMENT_IN_PROGRESS, 409 IDEMPOTENCY_KEY_CONFLICT | V33: ORD-18; ORD-19; DSC-04 | W33: G05; G35 | X33: =COUNTIF(Test_Cases!$B$2:$B$1000,A33) -> 10 | Y33: =IF(X33=0,"NO TEST",IF(X33<3,"THIN","OK")) -> OK
A34: ORD-07 | B34: Order | C34: Confirm received / Buyer xác nhận đã nhận hàng | D34: Public API | E34: POST /api/v1/orders/{orderId}/confirm-received?orderType= | F34: P2 | G34: 4 | H34: S | I34: ADJUSTED | J34: Behind a feature flag, default OFF: buyer early confirmation is OPEN (SRS COM-ORD-009, OQ-11). Two entry points exist (Fulfillment FUL-23, G08). | K34: 3.4.3.2 | L34: COM-ORD-009 | M34: ORDER.CONFIRM_RECEIVED (NEW) / Buyer | N34: orders, auction_orders, order_status_history, outbox_messages | O34: orders, auction_orders | P34: - | Q34: OrderCompleted | S34: CAS DELIVERED -> COMPLETED | T34: buyer_id = sub; status DELIVERED; COMPLETED opens rating (User) and triggers seller payout (Wallet) + invoice. | U34: 409 ORDER_STATE_CONFLICT | V34: ORD-18 | W34: G08 | X34: =COUNTIF(Test_Cases!$B$2:$B$1000,A34) -> 5 | Y34: =IF(X34=0,"NO TEST",IF(X34<3,"THIN","OK")) -> OK
A35: ORD-08 | B35: Order | C35: Auto-complete delivered orders / Job tự hoàn tất đơn | D35: Job | E35: mỗi giờ | F35: P1 | G35: 3 | H35: S | I35: UNCHANGED | J35: Interval hourly per Events spec 3.4. 'No open dispute' check has no data model. | K35: 3.4.3.2 | L35: COM-ORD-009 | M35: System | N35: orders, auction_orders, order_status_history, outbox_messages | O35: orders, auction_orders, system_settings | P35: - | Q35: OrderCompleted (SYSTEM) | S35: Batch 200, SKIP LOCKED, CAS | T35: DELIVERED older than ORDER_AUTO_COMPLETE_DAYS(7, proposed) -> COMPLETED; both order tables. | V35: ORD-18; ORD-26 | W35: G19 | X35: =COUNTIF(Test_Cases!$B$2:$B$1000,A35) -> 3 | Y35: =IF(X35=0,"NO TEST",IF(X35<3,"THIN","OK")) -> OK
A36: ORD-09 | B36: Order | C36: Seller response timeout / Job quá hạn seller phản hồi | D36: Job | E36: mỗi 1 phút | F36: P0 | G36: 3 | H36: M | I36: UNCHANGED | K36: 3.4.3.2; 3.4.2.4 | L36: COM-ORD-007; COM-CNL-002; COM-RFD-001; COM-AUC-007 | M36: System | N36: orders, auction_orders, order_cancellations, order_refunds, order_status_history, discount_codes, discount_code_usages, saga_state, outbox_messages | O36: orders, auction_orders | P36: Wallet refund; Fulfillment release; User penalty (via events) | Q36: OrderCancelled (SELLER_NO_RESPONSE, SYSTEM); OrderRefundRequested | S36: Every minute; batch + SKIP LOCKED; per-order saga | T36: status=PAID and seller_respond_deadline_at < now -> cancel + 100% refund. | V36: ORD-18; ORD-06 | W36: G05 | X36: =COUNTIF(Test_Cases!$B$2:$B$1000,A36) -> 3 | Y36: =IF(X36=0,"NO TEST",IF(X36<3,"THIN","OK")) -> OK
A37: ORD-10 | B37: Order | C37: Handle shipment events / Nhận sự kiện vận chuyển | D37: Event consumer | E37: shipment.* | F37: P0 | G37: 3 | H37: L | I37: ADJUSTED | J37: Per SRS 3.4.3 / OQ-11 and Events spec 2.5: ShipmentFailed / ShipmentReturned are NOT automated. Fulfillment FUL-17 emits only Delivered / DeliveryFailed (G07). | K37: 3.4.3.2 | L37: COM-ORD-008; COM-AUC-007 | M37: System | N37: inbox_messages, orders, auction_orders, order_status_history, order_cancellations, order_refunds, outbox_messages | O37: orders, auction_orders | P37: Fulfillment shipment events | Q37: OrderShipped; OrderDelivered | R37: ShipmentPickedUp; ShipmentInTransit; ShipmentDelivered; ShipmentFailed; ShipmentReturned | S37: Inbox; out-of-order tolerant (Delivered may arrive before InTransit) | T37: PickedUp -> SHIPPING (shipped_at); InTransit -> record only; Delivered -> DELIVERED (2 history rows if from CONFIRMED); Failed / Returned -> log + alert Support, no state change, no refund. | V37: ORD-18; ORD-24 | W37: G07; G25 | X37: =COUNTIF(Test_Cases!$B$2:$B$1000,A37) -> 4 | Y37: =IF(X37=0,"NO TEST",IF(X37<3,"THIN","OK")) -> OK
A38: ORD-11 | B38: Order | C38: Admin list orders / Quản trị xem tất cả đơn | D38: Public API | E38: GET /api/v1/admin/orders | F38: P1 | G38: 3 | H38: M | I38: UNCHANGED | K38: 3.4.3.5 | L38: COM-ORD-010 | M38: ORDER.LIST / Admin, Support | O38: orders, auction_orders | P38: User batch lookup of buyer/seller names | S38: Read-only | T38: At least one filter or date range; range<=1y; size<=100; audit sensitive field access. | U38: 400 VALIDATION_ERROR | W38: G11 | X38: =COUNTIF(Test_Cases!$B$2:$B$1000,A38) -> 5 | Y38: =IF(X38=0,"NO TEST",IF(X38<3,"THIN","OK")) -> OK
A39: ORD-12 | B39: Order | C39: Admin update order status / Admin chỉnh trạng thái ngoại lệ | D39: Public API | E39: PATCH /api/v1/admin/orders/{orderId}/status?orderType= | F39: P1 | G39: 3 | H39: M | I39: UNCHANGED | K39: 3.4.3.5 | L39: COM-ORD-010; COM-ORD-011; COM-PLT-007 | M39: ORDER.UPDATE_STATUS (NEW) / Admin | N39: orders, auction_orders, order_status_history, outbox_messages | O39: orders, auction_orders | P39: Event Log (audit, via event) | Q39: Event of target status (OrderDelivered / OrderCompleted ...) | S39: CAS via OrderStateMachine | T39: Forward whitelist only; never to CANCELLED, REFUNDED, PAID; reason >= 10 chars; actor ADMIN. | U39: 400 VALIDATION_ERROR, 409 INVALID_TRANSITION | V39: ORD-18 | X39: =COUNTIF(Test_Cases!$B$2:$B$1000,A39) -> 7 | Y39: =IF(X39=0,"NO TEST",IF(X39<3,"THIN","OK")) -> OK
A40: ORD-13 | B40: Order | C40: Admin/Support refund / Hoàn tiền thủ công | D40: Public API | E40: POST /api/v1/admin/orders/{orderId}/refund?orderType= | F40: P1 | G40: 3 | H40: M | I40: UNCHANGED | K40: 3.4.2.4; 3.4.3.5; 3.4.3.7 | L40: COM-RFD-001; COM-RFD-002; COM-RFD-005 | M40: ORDER.REFUND / Admin, Support | N40: order_refunds, order_status_history, idempotency_keys, outbox_messages | O40: orders, auction_orders, order_cancellations | P40: Wallet refund (async) | Q40: OrderRefundRequested | S40: Idempotency-Key required; unique active refund per order | T40: Status in DELIVERED | COMPLETED | CANCELLED(paid, not yet refunded); MVP full amount only; does not write order_cancellations. | U40: 409 REFUND_NOT_ALLOWED, 409 REFUND_ALREADY_REQUESTED, 409 IDEMPOTENCY_KEY_CONFLICT | V40: ORD-19; ORD-18 | W40: G05; G17 | X40: =COUNTIF(Test_Cases!$B$2:$B$1000,A40) -> 8 | Y40: =IF(X40=0,"NO TEST",IF(X40<3,"THIN","OK")) -> OK
...

Sheet Trace_Matrix
A1: COM requirement | B1: Module | C1: Requirement (short) | D1: System SRS section | E1: MoSCoW | F1: Backlog IDs | G1: # Functions | H1: API / trigger | I1: DB tables | J1: Events | K1: Integrated services | L1: # Test cases | M1: Coverage | N1: Open gaps
A2: COM-CART-001 | B2: Cart | C2: Cart lifecycle: 1 ACTIVE cart per buyer, lazy create | D2: 3.4.1.1 | E2: Must | F2: CART-01, CART-02 | G2: =SUMPRODUCT(--ISNUMBER(SEARCH(A2,Backlog!$L$2:$L$58))) -> 2 | H2: CART-01: GET /api/v1/carts/me; CART-02: POST /api/v1/carts/me/items | I2: cart_items, carts, checkout_groups, outbox_messages, system_settings | J2: CartCreated; CartItemAdded | K2: Catalog CAT-39; Catalog CAT-39 / CAT-24 | L2: =SUMPRODUCT(--ISNUMBER(SEARCH(A2,Test_Cases!$D$2:$D$1000))) -> 18 | M2: =IF(G2=0,"GAP - no function",IF(L2=0,"NO TEST",IF(L2<3,"THIN","COVERED"))) -> COVERED | N2: G09
A3: COM-CART-002 | B3: Cart | C3: Add item (merge by sku, limits 99/50, no own/auction product) | D3: 3.4.1.1; 3.4.1.2 | E3: Must | F3: CART-02 | G3: =SUMPRODUCT(--ISNUMBER(SEARCH(A3,Backlog!$L$2:$L$58))) -> 1 | H3: CART-02: POST /api/v1/carts/me/items | I3: cart_items, carts, checkout_groups, outbox_messages, system_settings | J3: CartCreated; CartItemAdded | K3: Catalog CAT-39 | L3: =SUMPRODUCT(--ISNUMBER(SEARCH(A3,Test_Cases!$D$2:$D$1000))) -> 14 | M3: =IF(G3=0,"GAP - no function",IF(L3=0,"NO TEST",IF(L3<3,"THIN","COVERED"))) -> COVERED | N3: G09
A4: COM-CART-003 | B4: Cart | C4: Update item quantity | D4: 3.4.1.3 | E4: Must | F4: CART-03 | G4: =SUMPRODUCT(--ISNUMBER(SEARCH(A4,Backlog!$L$2:$L$58))) -> 1 | H4: CART-03: PATCH /api/v1/carts/me/items/{cartItemId} | I4: cart_items, carts, checkout_groups, outbox_messages | J4: CartItemUpdated | K4: Catalog CAT-39 | L4: =SUMPRODUCT(--ISNUMBER(SEARCH(A4,Test_Cases!$D$2:$D$1000))) -> 11 | M4: =IF(G4=0,"GAP - no function",IF(L4=0,"NO TEST",IF(L4<3,"THIN","COVERED"))) -> COVERED | N4: G09
A5: COM-CART-004 | B5: Cart | C5: Remove item(s) | D5: 3.4.1.4 | E5: Must | F5: CART-04, CART-05 | G5: =SUMPRODUCT(--ISNUMBER(SEARCH(A5,Backlog!$L$2:$L$58))) -> 2 | H5: CART-04: DELETE /api/v1/carts/me/items/{cartItemId}; CART-05: POST /api/v1/carts/me/items:bulk-remove | I5: cart_items, carts, checkout_groups, outbox_messages | J5: CartItemRemoved; CartItemRemoved (1 event per batch) | L5: =SUMPRODUCT(--ISNUMBER(SEARCH(A5,Test_Cases!$D$2:$D$1000))) -> 9 | M5: =IF(G5=0,"GAP - no function",IF(L5=0,"NO TEST",IF(L5<3,"THIN","COVERED"))) -> COVERED
A6: COM-CART-005 | B6: Cart | C6: View cart and pricing estimate | D6: 3.4.1.5 | E6: Must | F6: CART-01, CART-07, CART-08 | G6: =SUMPRODUCT(--ISNUMBER(SEARCH(A6,Backlog!$L$2:$L$58))) -> 3 | H6: CART-01: GET /api/v1/carts/me; CART-07: PricingService.calculate(items, address?, vouchers?); CART-08: GET /api/v1/carts/me/summary | I6: cart_items, carts, system_settings | K6: Catalog CAT-39 / CAT-24; DSC-02 | L6: =SUMPRODUCT(--ISNUMBER(SEARCH(A6,Test_Cases!$D$2:$D$1000))) -> 11 | M6: =IF(G6=0,"GAP - no function",IF(L6=0,"NO TEST",IF(L6<3,"THIN","COVERED"))) -> COVERED | N6: G09; G20; G23
A7: COM-CART-006 | B7: Cart | C7: Validate cart before checkout | D7: 3.4.1.6 | E7: Must | F7: CART-06 | G7: =SUMPRODUCT(--ISNUMBER(SEARCH(A7,Backlog!$L$2:$L$58))) -> 1 | H7: CART-06: POST /api/v1/carts/me/validate (+ internal CartValidator dùn | I7: cart_items, carts | K7: Catalog CAT-39 / CAT-24 | L7: =SUMPRODUCT(--ISNUMBER(SEARCH(A7,Test_Cases!$D$2:$D$1000))) -> 6 | M7: =IF(G7=0,"GAP - no function",IF(L7=0,"NO TEST",IF(L7<3,"THIN","COVERED"))) -> COVERED | N7: G09
A8: COM-CART-007 | B8: Cart | C8: Cart expiry job (ABANDONED) | D8: 3.4.1.1 | E8: Should | F8: CART-09 | G8: =SUMPRODUCT(--ISNUMBER(SEARCH(A8,Backlog!$L$2:$L$58))) -> 1 | H8: CART-09: chạy mỗi giờ (@Scheduled + ShedLock) | I8: carts, checkout_groups, outbox_messages, system_settings | J8: CartExpired | L8: =SUMPRODUCT(--ISNUMBER(SEARCH(A8,Test_Cases!$D$2:$D$1000))) -> 3 | M8: =IF(G8=0,"GAP - no function",IF(L8=0,"NO TEST",IF(L8<3,"THIN","COVERED"))) -> COVERED | N8: G26
A9: COM-CART-008 | B9: Cart | C9: Cleanup by Catalog/User events | D9: 3.4.1.4 | E9: Should | F9: CART-11 | G9: =SUMPRODUCT(--ISNUMBER(SEARCH(A9,Backlog!$L$2:$L$58))) -> 1 | H9: CART-11: topics: catalog.*, user.* | I9: cart_items, carts, inbox_messages | J9: ProductDeleted; ProductStatusChanged; UserDeleted | K9: Catalog / User events | L9: =SUMPRODUCT(--ISNUMBER(SEARCH(A9,Test_Cases!$D$2:$D$1000))) -> 4 | M9: =IF(G9=0,"GAP - no function",IF(L9=0,"NO TEST",IF(L9<3,"THIN","COVERED"))) -> COVERED
A10: COM-CART-009 | B10: Cart | C10: Guest cart / merge on login (OPEN OQ-04) | D10: 3.4.1.1 | E10: Could | F10: CART-10 | G10: =SUMPRODUCT(--ISNUMBER(SEARCH(A10,Backlog!$L$2:$L$58))) -> 1 | H10: CART-10: POST /api/v1/carts/me/merge | I10: cart_items, carts, outbox_messages, system_settings | J10: CartItemAdded | K10: Catalog CAT-39; Fulfillment FUL-04 | L10: =SUMPRODUCT(--ISNUMBER(SEARCH(A10,Test_Cases!$D$2:$D$1000))) -> 6 | M10: =IF(G10=0,"GAP - no function",IF(L10=0,"NO TEST",IF(L10<3,"THIN","COVERED"))) -> COVERED | N10: G23
A11: COM-CHK-001 | B11: Checkout | C11: Start checkout (preview + create) | D11: 3.4.2.1 | E11: Must | F11: CHK-01, CHK-02 | G11: =SUMPRODUCT(--ISNUMBER(SEARCH(A11,Backlog!$L$2:$L$58))) -> 2 | H11: CHK-01: POST /api/v1/checkout/preview; CHK-02: POST /api/v1/checkout | I11: cart_items, carts, checkout_groups, daily_order_sequences, discount_code_scopes, discount_code_usages, discount_codes, idempotency_keys, order_items, order_status_history, orders, outbox_messages, saga_state, system_settings | J11: CheckoutStarted; InventoryReserved (Fulfillment, async variant); OrderCreated (per order) | K11: Catalog CAT-39; Catalog CAT-39/24; Fulfillment FUL-12 shipping quote | L11: =SUMPRODUCT(--ISNUMBER(SEARCH(A11,Test_Cases!$D$2:$D$1000))) -> 22 | M11: =IF(G11=0,"GAP - no function",IF(L11=0,"NO TEST",IF(L11<3,"THIN","COVERED"))) -> COVERED | N11: G05; G06; G09; G11
A12: COM-CHK-002 | B12: Checkout | C12: Split orders per seller | D12: 3.4.2.1 | E12: Must | F12: CHK-02 | G12: =SUMPRODUCT(--ISNUMBER(SEARCH(A12,Backlog!$L$2:$L$58))) -> 1 | H12: CHK-02: POST /api/v1/checkout | I12: cart_items, carts, checkout_groups, daily_order_sequences, discount_code_usages, discount_codes, idempotency_keys, order_items, order_status_history, orders, outbox_messages, saga_state, system_settings | J12: CheckoutStarted; InventoryReserved (Fulfillment, async variant); OrderCreated (per order) | K12: Catalog CAT-39 | L12: =SUMPRODUCT(--ISNUMBER(SEARCH(A12,Test_Cases!$D$2:$D$1000))) -> 15 | M12: =IF(G12=0,"GAP - no function",IF(L12=0,"NO TEST",IF(L12<3,"THIN","COVERED"))) -> COVERED | N12: G06; G11
A13: COM-CHK-003 | B13: Checkout | C13: Per-order pricing + invariant | D13: 3.4.1.5 | E13: Must | F13: CART-07, CHK-01, CHK-02 | G13: =SUMPRODUCT(--ISNUMBER(SEARCH(A13,Backlog!$L$2:$L$58))) -> 3 | H13: CART-07: PricingService.calculate(items, address?, vouchers?); CHK-01: POST /api/v1/checkout/preview; CHK-02: POST /api/v1/checkout | I13: cart_items, carts, checkout_groups, daily_order_sequences, discount_code_scopes, discount_code_usages, discount_codes, idempotency_keys, order_items, order_status_history, orders, outbox_messages, saga_state, system_settings | J13: CheckoutStarted; InventoryReserved (Fulfillment, async variant); OrderCreated (per order) | K13: Catalog CAT-39; Catalog CAT-39/24; Fulfillment FUL-12 shipping quote; DSC-02 | L13: =SUMPRODUCT(--ISNUMBER(SEARCH(A13,Test_Cases!$D$2:$D$1000))) -> 25 | M13: =IF(G13=0,"GAP - no function",IF(L13=0,"NO TEST",IF(L13<3,"THIN","COVERED"))) -> COVERED | N13: G05; G06; G09; G11; G20; G23
A14: COM-CHK-004 | B14: Checkout | C14: Shipping fee quote | D14: 3.4.2.1 | E14: Must | F14: CHK-01 | G14: =SUMPRODUCT(--ISNUMBER(SEARCH(A14,Backlog!$L$2:$L$58))) -> 1 | H14: CHK-01: POST /api/v1/checkout/preview | I14: cart_items, carts, discount_code_scopes, discount_code_usages, discount_codes, system_settings | K14: Catalog CAT-39/24; Fulfillment FUL-12 shipping quote | L14: =SUMPRODUCT(--ISNUMBER(SEARCH(A14,Test_Cases!$D$2:$D$1000))) -> 6 | M14: =IF(G14=0,"GAP - no function",IF(L14=0,"NO TEST",IF(L14<3,"THIN","COVERED"))) -> COVERED | N14: G05; G09
A15: COM-CHK-005 | B15: Checkout | C15: Persist group + orders in one TX | D15: 3.4.3.1 | E15: Must | F15: CHK-02 | G15: =SUMPRODUCT(--ISNUMBER(SEARCH(A15,Backlog!$L$2:$L$58))) -> 1 | H15: CHK-02: POST /api/v1/checkout | I15: cart_items, carts, checkout_groups, daily_order_sequences, discount_code_usages, discount_codes, idempotency_keys, order_items, order_status_history, orders, outbox_messages, saga_state, system_settings | J15: CheckoutStarted; InventoryReserved (Fulfillment, async variant); OrderCreated (per order) | K15: Catalog CAT-39 | L15: =SUMPRODUCT(--ISNUMBER(SEARCH(A15,Test_Cases!$D$2:$D$1000))) -> 16 | M15: =IF(G15=0,"GAP - no function",IF(L15=0,"NO TEST",IF(L15<3,"THIN","COVERED"))) -> COVERED | N15: G06; G11
A16: COM-CHK-006 | B16: Checkout | C16: Reserve voucher and inventory | D16: 3.4.3.8 | E16: Must | F16: CHK-02 | G16: =SUMPRODUCT(--ISNUMBER(SEARCH(A16,Backlog!$L$2:$L$58))) -> 1 | H16: CHK-02: POST /api/v1/checkout | I16: cart_items, carts, checkout_groups, daily_order_sequences, discount_code_usages, discount_codes, idempotency_keys, order_items, order_status_history, orders, outbox_messages, saga_state, system_settings | J16: CheckoutStarted; InventoryReserved (Fulfillment, async variant); OrderCreated (per order) | K16: Catalog CAT-39 | L16: =SUMPRODUCT(--ISNUMBER(SEARCH(A16,Test_Cases!$D$2:$D$1000))) -> 15 | M16: =IF(G16=0,"GAP - no function",IF(L16=0,"NO TEST",IF(L16<3,"THIN","COVERED"))) -> COVERED | N16: G06; G11
A17: COM-CHK-007 | B17: Checkout | C17: Block parallel checkout per cart | D17: 3.4.2.1 | E17: Must | F17: CHK-02 | G17: =SUMPRODUCT(--ISNUMBER(SEARCH(A17,Backlog!$L$2:$L$58))) -> 1 | H17: CHK-02: POST /api/v1/checkout | I17: cart_items, carts, checkout_groups, daily_order_sequences, discount_code_usages, discount_codes, idempotency_keys, order_items, order_status_history, orders, outbox_messages, saga_state, system_settings | J17: CheckoutStarted; InventoryReserved (Fulfillment, async variant); OrderCreated (per order) | K17: Catalog CAT-39 | L17: =SUMPRODUCT(--ISNUMBER(SEARCH(A17,Test_Cases!$D$2:$D$1000))) -> 16 | M17: =IF(G17=0,"GAP - no function",IF(L17=0,"NO TEST",IF(L17<3,"THIN","COVERED"))) -> COVERED | N17: G06; G11
A18: COM-CHK-008 | B18: Checkout | C18: Checkout expiry job | D18: 3.4.2.4; 3.4.3.8 | E18: Must | F18: CHK-06, ORD-22 | G18: =SUMPRODUCT(--ISNUMBER(SEARCH(A18,Backlog!$L$2:$L$58))) -> 2 | H18: CHK-06: mỗi 1 phút (+ consumer InventoryReservationExpired làm lưới ; ORD-22: inventory.* | I18: checkout_groups, discount_code_usages, discount_codes, inbox_messages, order_cancellations, order_status_history, orders, outbox_messages, saga_state | J18: CheckoutExpired; InventoryReleased; InventoryReservationExpired; OrderCancelled (PAYMENT_TIMEOUT, SYSTEM) | K18: Fulfillment events; Wallet payment status by referenceIds | L18: =SUMPRODUCT(--ISNUMBER(SEARCH(A18,Test_Cases!$D$2:$D$1000))) -> 8 | M18: =IF(G18=0,"GAP - no function",IF(L18=0,"NO TEST",IF(L18<3,"THIN","COVERED"))) -> COVERED | N18: G05; G06
A19: COM-CHK-009 | B19: Checkout | C19: Checkout group view / history | D19: 3.4.2.3 | E19: Must | F19: CHK-04 | G19: =SUMPRODUCT(--ISNUMBER(SEARCH(A19,Backlog!$L$2:$L$58))) -> 1 | H19: CHK-04: GET /api/v1/checkout-groups/{checkoutGroupId} | I19: checkout_groups, orders | L19: =SUMPRODUCT(--ISNUMBER(SEARCH(A19,Test_Cases!$D$2:$D$1000))) -> 4 | M19: =IF(G19=0,"GAP - no function",IF(L19=0,"NO TEST",IF(L19<3,"THIN","COVERED"))) -> COVERED
A20: COM-CHK-010 | B20: Checkout | C20: Buyer cancels unpaid checkout (PROPOSED) | D20: 3.4.2.4 | E20: Should | F20: CHK-05 | G20: =SUMPRODUCT(--ISNUMBER(SEARCH(A20,Backlog!$L$2:$L$58))) -> 1 | H20: CHK-05: POST /api/v1/checkout-groups/{checkoutGroupId}/cancel | I20: checkout_groups, discount_code_usages, discount_codes, order_cancellations, order_status_history, orders, outbox_messages, saga_state | J20: CheckoutCancelled; OrderCancelled (per order) | K20: Wallet | L20: =SUMPRODUCT(--ISNUMBER(SEARCH(A20,Test_Cases!$D$2:$D$1000))) -> 7 | M20: =IF(G20=0,"GAP - no function",IF(L20=0,"NO TEST",IF(L20<3,"THIN","COVERED"))) -> COVERED | N20: G05
A21: COM-PAY-001 | B21: Payment (Commerce side) | C21: Initiate payment for group / auction order | D21: 3.4.2.2 | E21: Must | F21: CHK-03, AO-03 | G21: =SUMPRODUCT(--ISNUMBER(SEARCH(A21,Backlog!$L$2:$L$58))) -> 2 | H21: CHK-03: POST /api/v1/checkout-groups/{checkoutGroupId}/pay; AO-03: POST /api/v1/auction-orders/{auctionOrderId}/pay | I21: auction_orders, checkout_groups, idempotency_keys, orders, outbox_messages, saga_state | J21: OrderCheckoutRequested (WALLET path, per WAL-05A); OrderCheckoutRequested (WALLET) | K21: Wallet WAL-05A; Wallet WAL-05A / WAL-05B | L21: =SUMPRODUCT(--ISNUMBER(SEARCH(A21,Test_Cases!$D$2:$D$1000))) -> 22 | M21: =IF(G21=0,"GAP - no function",IF(L21=0,"NO TEST",IF(L21<3,"THIN","COVERED"))) -> COVERED | N21: G05; G16
A22: COM-PAY-002 | B22: Payment (Commerce side) | C22: Payment success handling | D22: 3.4.3.7; 3.4.3.8 | E22: Must | F22: PAY-01 | G22: =SUMPRODUCT(--ISNUMBER(SEARCH(A22,Backlog!$L$2:$L$58))) -> 1 | H22: PAY-01: PaymentSucceeded | PaymentFailed | PaymentExpired (event do | I22: auction_orders, cart_items, carts, checkout_groups, discount_code_usages, discount_codes, inbox_messages, order_items, order_refunds, order_status_history, orders, outbox_messages, saga_state | J22: CheckoutCompleted (not in SRS 5.2); OrderPaid (per order); OrderPaymentFailed; OrderRefundRequested (late/mismatch); PaymentSucceeded / PaymentFailed / PaymentExpired (as written); WalletDebitedSuccess / WalletDebitFailed (target) | K22: Wallet events | L22: =SUMPRODUCT(--ISNUMBER(SEARCH(A22,Test_Cases!$D$2:$D$1000))) -> 5 | M22: =IF(G22=0,"GAP - no function",IF(L22=0,"NO TEST",IF(L22<3,"THIN","COVERED"))) -> COVERED | N22: G05
A23: COM-PAY-003 | B23: Payment (Commerce side) | C23: Payment failure / retry limit | D23: 3.4.3.8 | E23: Must | F23: PAY-01 | G23: =SUMPRODUCT(--ISNUMBER(SEARCH(A23,Backlog!$L$2:$L$58))) -> 1 | H23: PAY-01: PaymentSucceeded | PaymentFailed | PaymentExpired (event do | I23: auction_orders, cart_items, carts, checkout_groups, discount_code_usages, discount_codes, inbox_messages, order_items, order_refunds, order_status_history, orders, outbox_messages, saga_state | J23: CheckoutCompleted (not in SRS 5.2); OrderPaid (per order); OrderPaymentFailed; OrderRefundRequested (late/mismatch); PaymentSucceeded / PaymentFailed / PaymentExpired (as written); WalletDebitedSuccess / WalletDebitFailed (target) | K23: Wallet events | L23: =SUMPRODUCT(--ISNUMBER(SEARCH(A23,Test_Cases!$D$2:$D$1000))) -> 4 | M23: =IF(G23=0,"GAP - no function",IF(L23=0,"NO TEST",IF(L23<3,"THIN","COVERED"))) -> COVERED | N23: G05
A24: COM-PAY-004 | B24: Payment (Commerce side) | C24: Late or mismatched payment -> refund | D24: 3.4.3.8 | E24: Must | F24: PAY-01 | G24: =SUMPRODUCT(--ISNUMBER(SEARCH(A24,Backlog!$L$2:$L$58))) -> 1 | H24: PAY-01: PaymentSucceeded | PaymentFailed | PaymentExpired (event do | I24: auction_orders, cart_items, carts, checkout_groups, discount_code_usages, discount_codes, inbox_messages, order_items, order_refunds, order_status_history, orders, outbox_messages, saga_state | J24: CheckoutCompleted (not in SRS 5.2); OrderPaid (per order); OrderPaymentFailed; OrderRefundRequested (late/mismatch); PaymentSucceeded / PaymentFailed / PaymentExpired (as written); WalletDebitedSuccess / WalletDebitFailed (target) | K24: Wallet events | L24: =SUMPRODUCT(--ISNUMBER(SEARCH(A24,Test_Cases!$D$2:$D$1000))) -> 5 | M24: =IF(G24=0,"GAP - no function",IF(L24=0,"NO TEST",IF(L24<3,"THIN","COVERED"))) -> COVERED | N24: G05
A25: COM-PAY-005 | B25: Payment (Commerce side) | C25: Auction order payment preconditions | D25: 3.4.2.2 | E25: Must | F25: AO-02, AO-03 | G25: =SUMPRODUCT(--ISNUMBER(SEARCH(A25,Backlog!$L$2:$L$58))) -> 2 | H25: AO-02: PUT /api/v1/auction-orders/{auctionOrderId}/shipping; AO-03: POST /api/v1/auction-orders/{auctionOrderId}/pay | I25: auction_orders, idempotency_keys | J25: OrderCheckoutRequested (WALLET) | K25: Fulfillment FUL-12; Wallet WAL-05A / WAL-05B | L25: =SUMPRODUCT(--ISNUMBER(SEARCH(A25,Test_Cases!$D$2:$D$1000))) -> 18 | M25: =IF(G25=0,"GAP - no function",IF(L25=0,"NO TEST",IF(L25<3,"THIN","COVERED"))) -> COVERED | N25: G05; G16
A26: COM-ORD-001 | B26: Order | C26: Order creation + order number | D26: 3.4.3.1 | E26: Must | F26: CHK-02, ORD-17, AO-01 | G26: =SUMPRODUCT(--ISNUMBER(SEARCH(A26,Backlog!$L$2:$L$58))) -> 3 | H26: CHK-02: POST /api/v1/checkout; ORD-17: SequenceService.next(seqType); AO-01: Consumer - AuctionSettled (AuctionWon ignored) | I26: auction_orders, cart_items, carts, checkout_groups, daily_order_sequences, discount_code_usages, discount_codes, idempotency_keys, inbox_messages, order_items, order_status_history, orders, outbox_messages, saga_state, system_settings | J26: AuctionSettled; CheckoutStarted; InventoryReserved (Fulfillment, async variant); OrderCreated (orderType=AUCTION); OrderCreated (per order) | K26: Catalog CAT-24; Catalog CAT-39 | L26: =SUMPRODUCT(--ISNUMBER(SEARCH(A26,Test_Cases!$D$2:$D$1000))) -> 22 | M26: =IF(G26=0,"GAP - no function",IF(L26=0,"NO TEST",IF(L26<3,"THIN","COVERED"))) -> COVERED | N26: G06; G11; G20; G21; G33
A27: COM-ORD-002 | B27: Order | C27: Buyer order list | D27: 3.4.3.4 | E27: Must | F27: ORD-01 | G27: =SUMPRODUCT(--ISNUMBER(SEARCH(A27,Backlog!$L$2:$L$58))) -> 1 | H27: ORD-01: GET /api/v1/orders | I27: auction_orders, order_items, orders | K27: User batch lookup of seller name | L27: =SUMPRODUCT(--ISNUMBER(SEARCH(A27,Test_Cases!$D$2:$D$1000))) -> 5 | M27: =IF(G27=0,"GAP - no function",IF(L27=0,"NO TEST",IF(L27<3,"THIN","COVERED"))) -> COVERED | N27: G11
A28: COM-ORD-003 | B28: Order | C28: Order detail + status history | D28: 3.4.3.3 | E28: Must | F28: ORD-02 | G28: =SUMPRODUCT(--ISNUMBER(SEARCH(A28,Backlog!$L$2:$L$58))) -> 1 | H28: ORD-02: GET /api/v1/orders/{orderId}?orderType=REGULAR|AUCTION | I28: auction_orders, order_cancellations, order_invoices, order_items, order_refunds, order_status_history, orders | K28: Fulfillment FUL-18/19/20 | L28: =SUMPRODUCT(--ISNUMBER(SEARCH(A28,Test_Cases!$D$2:$D$1000))) -> 5 | M28: =IF(G28=0,"GAP - no function",IF(L28=0,"NO TEST",IF(L28<3,"THIN","COVERED"))) -> COVERED
A29: COM-ORD-004 | B29: Order | C29: Seller order list (paid only) | D29: 3.4.3.4 | E29: Must | F29: ORD-03 | G29: =SUMPRODUCT(--ISNUMBER(SEARCH(A29,Backlog!$L$2:$L$58))) -> 1 | H29: ORD-03: GET /api/v1/seller/orders | I29: auction_orders, orders | L29: =SUMPRODUCT(--ISNUMBER(SEARCH(A29,Test_Cases!$D$2:$D$1000))) -> 4 | M29: =IF(G29=0,"GAP - no function",IF(L29=0,"NO TEST",IF(L29<3,"THIN","COVERED"))) -> COVERED
A30: COM-ORD-005 | B30: Order | C30: Seller accepts order | D30: 3.4.3.2 | E30: Must | F30: ORD-04 | G30: =SUMPRODUCT(--ISNUMBER(SEARCH(A30,Backlog!$L$2:$L$58))) -> 1 | H30: ORD-04: POST /api/v1/seller/orders/{orderId}/accept?orderType= | I30: auction_orders, order_status_history, orders, outbox_messages | J30: OrderConfirmed (renamed from OrderSellerAccepted, spec 2.4.5 PROPOSED) | K30: Fulfillment creates shipment asynchronously on OrderConfirme | L30: =SUMPRODUCT(--ISNUMBER(SEARCH(A30,Test_Cases!$D$2:$D$1000))) -> 9 | M30: =IF(G30=0,"GAP - no function",IF(L30=0,"NO TEST",IF(L30<3,"THIN","COVERED"))) -> COVERED | N30: G14
A31: COM-ORD-006 | B31: Order | C31: Seller rejects order (PROPOSED) | D31: 3.4.3.2 | E31: Must | F31: ORD-05 | G31: =SUMPRODUCT(--ISNUMBER(SEARCH(A31,Backlog!$L$2:$L$58))) -> 1 | H31: ORD-05: POST /api/v1/seller/orders/{orderId}/reject?orderType= | I31: auction_orders, discount_code_usages, discount_codes, order_cancellations, order_refunds, order_status_history, orders, outbox_messages, saga_state | J31: OrderCancelled (SELLER_REJECTED, SELLER); OrderRefundRequested | K31: Wallet refund via OrderRefundRequested; Fulfillment release | L31: =SUMPRODUCT(--ISNUMBER(SEARCH(A31,Test_Cases!$D$2:$D$1000))) -> 6 | M31: =IF(G31=0,"GAP - no function",IF(L31=0,"NO TEST",IF(L31<3,"THIN","COVERED"))) -> COVERED | N31: G05; G13
A32: COM-ORD-007 | B32: Order | C32: Seller response timeout job | D32: 3.4.3.2 | E32: Must | F32: ORD-09 | G32: =SUMPRODUCT(--ISNUMBER(SEARCH(A32,Backlog!$L$2:$L$58))) -> 1 | H32: ORD-09: mỗi 1 phút | I32: auction_orders, discount_code_usages, discount_codes, order_cancellations, order_refunds, order_status_history, orders, outbox_messages, saga_state | J32: OrderCancelled (SELLER_NO_RESPONSE, SYSTEM); OrderRefundRequested | K32: Wallet refund; Fulfillment release; User penalty | L32: =SUMPRODUCT(--ISNUMBER(SEARCH(A32,Test_Cases!$D$2:$D$1000))) -> 4 | M32: =IF(G32=0,"GAP - no function",IF(L32=0,"NO TEST",IF(L32<3,"THIN","COVERED"))) -> COVERED | N32: G05
A33: COM-ORD-008 | B33: Order | C33: Shipment sync (shipping/delivered) | D33: 3.4.3.2 | E33: Must | F33: ORD-10 | G33: =SUMPRODUCT(--ISNUMBER(SEARCH(A33,Backlog!$L$2:$L$58))) -> 1 | H33: ORD-10: shipment.* | I33: auction_orders, inbox_messages, order_cancellations, order_refunds, order_status_history, orders, outbox_messages | J33: OrderDelivered; OrderShipped; ShipmentDelivered; ShipmentFailed; ShipmentInTransit; ShipmentPickedUp; ShipmentReturned | K33: Fulfillment shipment events | L33: =SUMPRODUCT(--ISNUMBER(SEARCH(A33,Test_Cases!$D$2:$D$1000))) -> 5 | M33: =IF(G33=0,"GAP - no function",IF(L33=0,"NO TEST",IF(L33<3,"THIN","COVERED"))) -> COVERED | N33: G07; G25
A34: COM-ORD-009 | B34: Order | C34: Complete order (buyer / auto) | D34: 3.4.3.2 | E34: Should | F34: ORD-07, ORD-08 | G34: =SUMPRODUCT(--ISNUMBER(SEARCH(A34,Backlog!$L$2:$L$58))) -> 2 | H34: ORD-07: POST /api/v1/orders/{orderId}/confirm-received?orderType=; ORD-08: mỗi giờ | I34: auction_orders, order_status_history, orders, outbox_messages, system_settings | J34: OrderCompleted; OrderCompleted (SYSTEM) | L34: =SUMPRODUCT(--ISNUMBER(SEARCH(A34,Test_Cases!$D$2:$D$1000))) -> 9 | M34: =IF(G34=0,"GAP - no function",IF(L34=0,"NO TEST",IF(L34<3,"THIN","COVERED"))) -> COVERED | N34: G08; G19
